### panic异常
Go的类型系统会在编译时捕获很多错误，但有些错误只能在运行时检查，如数组访问越界、空指针引用等。这些运行时错误会引起panic异常。

一般而言，当panic异常发生时，程序会中断运行，并立即执行在该goroutine（可以先理解成线程）中被延迟的函数（defer 机制）。随后，程序崩溃并输出日志信息。日志信息包括panic value和函数调用的堆栈跟踪信息。panic value通常是某种错误信息。对于每个goroutine，日志信息中都会有与之相对的，发生panic时的函数调用堆栈跟踪信息。通常，我们不需要再次运行程序去定位问题，日志信息已经提供了足够的诊断依据。因此，在我们填写问题报告时，一般会将panic异常和日志信息一并记录。

不是所有的panic异常都来自运行时，直接调用内置的panic函数也会引发panic异常；panic函数接受任何值作为参数。当某些不应该发生的场景发生时，我们就应该调用panic。比如，当程序到达了某条逻辑上不可能到达的路径：
```Go
switch s := suit(drawCard()); s {
case "Spades":                                // ...
case "Hearts":                                // ...
case "Diamonds":                              // ...
case "Clubs":                                 // ...
default:
    panic(fmt.Sprintf("invalid suit %q", s)) // Joker?
}
```

### 错误处理

- 程序中出现后panic异常后，程序被中断，无法继续执行
```Go
package main

import "fmt"

func main() {
	test()
	fmt.Println("上面的除法操作执行成功")
}

func test() {
	num1 := 10
	num2 := 0
    fmt.Println(num1, num2)
	result := num1 / num2
	fmt.Println(result)
}
```
```
10  0
panic: runtime error: integer divide by zero

goroutine 1 [running]:
main.test()
        C:/code_go/test_panic/test/main.go:13 +0x9
main.main()
        C:/code_go/test_panic/test/main.go:6 +0x13
exit status 2
```

- 错误处理/捕获机制：
defer+recover机制处理错误
recover函数：
`func recover() interface{}`
内建函数recover允许程序管理恐慌过程中的Go程。在defer的函数中，执行recover调用会取回传至panic调用的错误值，恢复正常执行，停止恐慌过程。若recover在defer的函数之外被调用，它将不会停止恐慌过程序列。在此情况下，或当该Go程不在恐慌过程中时，或提供给panic的实参为nil时，recover就会返回nil。
```Go
package main

import "fmt"

func main() {
	test()
	fmt.Println("上面的除法操作执行成功")
}

func test() {
	// 利用defer和recover来捕获恐慌，defer后加上一个匿名函数的调用
	defer func() {
		// 调用recover内置函数，可以捕获错误
		err := recover()
		// 如果没有捕获错误，返回值为零值：nil
		if err != nil {
			fmt.Println("错误被捕获")
			fmt.Println("err:", err)
		}
	}()
	num1 := 10
	num2 := 0
	fmt.Println(num1, num2)
	result := num1 / num2
	fmt.Println(result)
}
```
> 10 0
> 错误被捕获
> err: runtime error: integer divide by zero
> 上面的除法操作执行成功


### 自定义错误
需要调用errors包下的New函数进行操作：返回一个error类型
`func New(text string) error`
使用字符串创建一个错误,请类比fmt包的Errorf方法，差不多可以认为是New(fmt.Sprintf(...))。
```Go
package main

import (
	"errors"
	"fmt"
)

func main() {
	err := test()
	if err != nil {
		fmt.Println("自定义错误：", err)
	}
	fmt.Println("上面的除法操作执行成功")
}

func test() (err error) {
	num1 := 10
	num2 := 0
	if num2 == 0 {
		// 抛出自定义错误
		return errors.New("除数不能为0")
	} else {
		// 如果除数不为0，则正常打印
		result := num1 / num2
		fmt.Println(result)
		// 如果没有错误，则返回零值
		return nil
	}
}
```
> 自定义错误： 除数不能为0
> 上面的除法操作执行成功

如果程序出现错误以后，后续代码没有必要执行，想让程序中断，退出程序：
可以借助builtin包下的内置函数：panic
`func panic(v interface{})`
内建函数panic停止当前Go程的正常执行。当函数F调用panic时，F的正常执行就会立刻停止。F中defer的所有函数先入后出执行后，F返回给其调用者G。G如同F一样行动，层层返回，直到该Go程中所有函数都按相反的顺序停止执行。之后，程序被终止，而错误情况会被报告，包括引发该恐慌的实参值，此终止序列称为恐慌过程。
```Go
package main

import (
	"errors"
	"fmt"
)

func main() {
	err := test()
	if err != nil {
		fmt.Println("自定义错误：", err)
		panic(err)
	}
	fmt.Println("上面的除法操作执行成功")
}

func test() (err error) {
	num1 := 10
	num2 := 0
	if num2 == 0 {
		// 抛出自定义错误
		return errors.New("除数不能为0")
	} else {
		// 如果除数不为0，则正常打印
		result := num1 / num2
		fmt.Println(result)
		// 如果没有错误，则返回零值
		return nil
	}
}
```
```
自定义错误： 除数不能为0
panic: 除数不能为0

goroutine 1 [running]:
main.main()
        C:/code_go/test_panic/test1/main.go:12 +0xd3
exit status 2
```